<?xml version="1.0"?>
<robot name="cartesian_robot">
    <link name="base_link">
    </link>

    <link name="x_axis_link"/>
    <link name="y_axis_link"/>
    <link name="z_axis_link"/>

    <link name="end_effector">
        <visual>
            <geometry>
                <sphere radius="0.5"/> 
            </geometry>            
        </visual>
        <collision>
            <geometry>
                <sphere radius="0.5"/> 
            </geometry>            
        </collision>
    </link>

    <joint name="x_axis_joint" type="prismatic">
        <parent link="base_link"/>
        <child link="x_axis_link"/>
        <axis xyz="1.0 0.0 0.0"/>        
        <limit lower="-1.0" upper="1.0" effort="1.0" velocity="1.0"/>
        <origin rpy="0 0 0" xyz="0 0 0"/>
    </joint>

    <joint name="y_axis_joint" type="prismatic">
        <parent link="x_axis_link"/>
        <child link="y_axis_link"/>
        <axis xyz="0.0 1.0 0.0"/>        
        <limit lower="-1.0" upper="1.0" effort="1.0" velocity="1.0"/>
        <origin rpy="0 0 0" xyz="0 0 0"/>
    </joint>

    <joint name="z_axis_joint" type="prismatic">
        <parent link="y_axis_link"/>
        <child link="z_axis_link"/>
        <axis xyz="0.0 0.0 -1.0"/>        
        <limit lower="-1.0" upper="1.0" effort="1.0" velocity="1.0"/>
        <origin rpy="0 0 0" xyz="0 0 0"/>
    </joint>

    <joint name="end_effector_joint" type="fixed">
        <parent link="z_axis_link"/>
        <child link="end_effector"/>
        <origin rpy="0 0 0" xyz="0 0 0"/>        
    </joint>
        


</robot>

